2020-03-18 15:08:43,983 ERROR: Exception on /search [GET] [in c:\users\alec\appdata\local\programs\python\python38\lib\site-packages\flask\app.py:1890]
Traceback (most recent call last):
  File "c:\users\alec\appdata\local\programs\python\python38\lib\site-packages\flask\app.py", line 2446, in wsgi_app
    response = self.full_dispatch_request()
  File "c:\users\alec\appdata\local\programs\python\python38\lib\site-packages\flask\app.py", line 1951, in full_dispatch_request
    rv = self.handle_user_exception(e)
  File "c:\users\alec\appdata\local\programs\python\python38\lib\site-packages\flask\app.py", line 1820, in handle_user_exception
    reraise(exc_type, exc_value, tb)
  File "c:\users\alec\appdata\local\programs\python\python38\lib\site-packages\flask\_compat.py", line 39, in reraise
    raise value
  File "c:\users\alec\appdata\local\programs\python\python38\lib\site-packages\flask\app.py", line 1949, in full_dispatch_request
    rv = self.dispatch_request()
  File "c:\users\alec\appdata\local\programs\python\python38\lib\site-packages\flask\app.py", line 1935, in dispatch_request
    return self.view_functions[rule.endpoint](**req.view_args)
  File "c:\users\alec\appdata\local\programs\python\python38\lib\site-packages\flask_login\utils.py", line 272, in decorated_view
    return func(*args, **kwargs)
  File "C:\Users\Alec\Documents\Development\FlaskStuff\microblog\app\main\routes.py", line 142, in search
    posts, total = Post.search(g.search_form.q.data, page,
  File "C:\Users\Alec\Documents\Development\FlaskStuff\microblog\app\models.py", line 15, in search
    ids, total = query_index(cls.__tablename__, expression, page, per_page)
  File "C:\Users\Alec\Documents\Development\FlaskStuff\microblog\app\search.py", line 19, in query_index
    search = current_app.elasticsearch.search(
  File "c:\users\alec\appdata\local\programs\python\python38\lib\site-packages\elasticsearch\client\utils.py", line 84, in _wrapped
    return func(*args, params=params, **kwargs)
  File "c:\users\alec\appdata\local\programs\python\python38\lib\site-packages\elasticsearch\client\__init__.py", line 1547, in search
    return self.transport.perform_request(
  File "c:\users\alec\appdata\local\programs\python\python38\lib\site-packages\elasticsearch\transport.py", line 351, in perform_request
    status, headers_response, data = connection.perform_request(
  File "c:\users\alec\appdata\local\programs\python\python38\lib\site-packages\elasticsearch\connection\http_urllib3.py", line 261, in perform_request
    self._raise_error(response.status, raw_data)
  File "c:\users\alec\appdata\local\programs\python\python38\lib\site-packages\elasticsearch\connection\base.py", line 181, in _raise_error
    raise HTTP_EXCEPTIONS.get(status_code, TransportError)(
elasticsearch.exceptions.NotFoundError: NotFoundError(404, 'index_not_found_exception', 'no such index [post]', post, index_or_alias)
2020-03-24 09:59:30,026 INFO: Microblog startup [in C:\Users\Alec\Documents\Development\FlaskStuff\microblog\app\__init__.py:77]
2020-03-24 10:05:43,381 INFO: Microblog startup [in C:\Users\Alec\Documents\Development\FlaskStuff\microblog\app\__init__.py:77]
2020-03-24 10:10:32,227 INFO: Microblog startup [in C:\Users\Alec\Documents\Development\FlaskStuff\microblog\app\__init__.py:77]
2020-03-24 10:21:21,833 INFO: Microblog startup [in C:\Users\Alec\Documents\Development\FlaskStuff\microblog\app\__init__.py:77]
2020-03-24 10:30:48,392 INFO: Microblog startup [in C:\Users\Alec\Documents\Development\FlaskStuff\microblog\app\__init__.py:77]
2020-03-24 10:30:51,881 INFO: Microblog startup [in C:\Users\Alec\Documents\Development\FlaskStuff\microblog\app\__init__.py:77]
2020-03-24 10:45:18,413 INFO: Microblog startup [in C:\Users\Alec\Documents\Development\FlaskStuff\microblog\app\__init__.py:77]
2020-03-24 10:46:20,942 INFO: Microblog startup [in C:\Users\Alec\Documents\Development\FlaskStuff\microblog\app\__init__.py:77]
2020-03-24 10:46:27,402 ERROR: Exception on /messages [GET] [in c:\users\alec\appdata\local\programs\python\python38\lib\site-packages\flask\app.py:1890]
Traceback (most recent call last):
  File "c:\users\alec\appdata\local\programs\python\python38\lib\site-packages\flask\app.py", line 2446, in wsgi_app
    response = self.full_dispatch_request()
  File "c:\users\alec\appdata\local\programs\python\python38\lib\site-packages\flask\app.py", line 1951, in full_dispatch_request
    rv = self.handle_user_exception(e)
  File "c:\users\alec\appdata\local\programs\python\python38\lib\site-packages\flask\app.py", line 1820, in handle_user_exception
    reraise(exc_type, exc_value, tb)
  File "c:\users\alec\appdata\local\programs\python\python38\lib\site-packages\flask\_compat.py", line 39, in reraise
    raise value
  File "c:\users\alec\appdata\local\programs\python\python38\lib\site-packages\flask\app.py", line 1949, in full_dispatch_request
    rv = self.dispatch_request()
  File "c:\users\alec\appdata\local\programs\python\python38\lib\site-packages\flask\app.py", line 1935, in dispatch_request
    return self.view_functions[rule.endpoint](**req.view_args)
  File "c:\users\alec\appdata\local\programs\python\python38\lib\site-packages\flask_login\utils.py", line 272, in decorated_view
    return func(*args, **kwargs)
  File "C:\Users\Alec\Documents\Development\FlaskStuff\microblog\app\main\routes.py", line 173, in messages
    current_user.add_notification('unread_message_count', 0)
  File "c:\users\alec\appdata\local\programs\python\python38\lib\site-packages\werkzeug\local.py", line 347, in __getattr__
    return getattr(self._get_current_object(), name)
AttributeError: 'User' object has no attribute 'add_notification'
2020-03-24 10:50:00,403 INFO: Microblog startup [in C:\Users\Alec\Documents\Development\FlaskStuff\microblog\app\__init__.py:77]
2020-03-24 10:50:06,311 INFO: Microblog startup [in C:\Users\Alec\Documents\Development\FlaskStuff\microblog\app\__init__.py:77]
2020-03-24 10:53:50,762 INFO: Microblog startup [in C:\Users\Alec\Documents\Development\FlaskStuff\microblog\app\__init__.py:77]
2020-03-25 14:54:14,422 INFO: Microblog startup [in C:\Users\Alec\Documents\Development\FlaskStuff\microblog\app\__init__.py:77]
2020-03-26 11:52:30,379 INFO: Microblog startup [in C:\Users\Alec\Documents\Development\FlaskStuff\microblog\app\__init__.py:77]
2020-03-26 12:17:28,511 INFO: Microblog startup [in C:\Users\Alec\Documents\Development\FlaskStuff\microblog\app\__init__.py:77]
2020-03-26 12:17:33,576 INFO: Microblog startup [in C:\Users\Alec\Documents\Development\FlaskStuff\microblog\app\__init__.py:77]
2020-03-26 12:26:37,056 INFO: Microblog startup [in C:\Users\Alec\Documents\Development\FlaskStuff\microblog\app\__init__.py:79]
2020-03-26 12:34:07,991 INFO: Microblog startup [in /mnt/c/Users/Alec/Documents/Development/FlaskStuff/microblog/app/__init__.py:79]
2020-03-26 12:48:20,944 INFO: Microblog startup [in /mnt/c/Users/Alec/Documents/Development/FlaskStuff/microblog/app/__init__.py:79]
2020-03-26 12:55:26,334 INFO: Microblog startup [in /mnt/c/Users/Alec/Documents/Development/FlaskStuff/microblog/app/__init__.py:79]
2020-03-26 12:55:32,198 INFO: Microblog startup [in /mnt/c/Users/Alec/Documents/Development/FlaskStuff/microblog/app/__init__.py:79]
2020-03-26 12:55:45,322 INFO: Microblog startup [in /mnt/c/Users/Alec/Documents/Development/FlaskStuff/microblog/app/__init__.py:79]
2020-03-26 12:58:43,888 INFO: Microblog startup [in /mnt/c/Users/Alec/Documents/Development/FlaskStuff/microblog/app/__init__.py:79]
2020-03-26 12:59:24,834 INFO: Microblog startup [in ./app/__init__.py:79]
2020-03-26 12:59:29,902 ERROR: Unhandled exception [in ./app/tasks.py:50]
Traceback (most recent call last):
  File "/home/areid/.local/lib/python3.6/site-packages/flask_mail.py", line 492, in send
    message.send(connection)
  File "/home/areid/.local/lib/python3.6/site-packages/flask_mail.py", line 427, in send
    connection.send(self)
  File "/home/areid/.local/lib/python3.6/site-packages/flask_mail.py", line 192, in send
    message.rcpt_options)
  File "/usr/lib/python3.6/smtplib.py", line 852, in sendmail
    self.ehlo_or_helo_if_needed()
  File "/usr/lib/python3.6/smtplib.py", line 600, in ehlo_or_helo_if_needed
    if not (200 <= self.ehlo()[0] <= 299):
  File "/usr/lib/python3.6/smtplib.py", line 440, in ehlo
    self.putcmd(self.ehlo_msg, name or self.local_hostname)
  File "/usr/lib/python3.6/smtplib.py", line 367, in putcmd
    self.send(str)
  File "/usr/lib/python3.6/smtplib.py", line 359, in send
    raise SMTPServerDisconnected('please run connect() first')
smtplib.SMTPServerDisconnected: please run connect() first

During handling of the above exception, another exception occurred:

Traceback (most recent call last):
  File "./app/tasks.py", line 47, in export_posts
    sync=True)
  File "./app/email.py", line 20, in send_email
    mail.send(msg)
  File "/home/areid/.local/lib/python3.6/site-packages/flask_mail.py", line 492, in send
    message.send(connection)
  File "/home/areid/.local/lib/python3.6/site-packages/flask_mail.py", line 152, in __exit__
    self.host.quit()
  File "/usr/lib/python3.6/smtplib.py", line 984, in quit
    res = self.docmd("quit")
  File "/usr/lib/python3.6/smtplib.py", line 420, in docmd
    self.putcmd(cmd, args)
  File "/usr/lib/python3.6/smtplib.py", line 367, in putcmd
    self.send(str)
  File "/usr/lib/python3.6/smtplib.py", line 359, in send
    raise SMTPServerDisconnected('please run connect() first')
smtplib.SMTPServerDisconnected: please run connect() first
