2020-03-18 15:08:43,983 ERROR: Exception on /search [GET] [in c:\users\alec\appdata\local\programs\python\python38\lib\site-packages\flask\app.py:1890]
Traceback (most recent call last):
  File "c:\users\alec\appdata\local\programs\python\python38\lib\site-packages\flask\app.py", line 2446, in wsgi_app
    response = self.full_dispatch_request()
  File "c:\users\alec\appdata\local\programs\python\python38\lib\site-packages\flask\app.py", line 1951, in full_dispatch_request
    rv = self.handle_user_exception(e)
  File "c:\users\alec\appdata\local\programs\python\python38\lib\site-packages\flask\app.py", line 1820, in handle_user_exception
    reraise(exc_type, exc_value, tb)
  File "c:\users\alec\appdata\local\programs\python\python38\lib\site-packages\flask\_compat.py", line 39, in reraise
    raise value
  File "c:\users\alec\appdata\local\programs\python\python38\lib\site-packages\flask\app.py", line 1949, in full_dispatch_request
    rv = self.dispatch_request()
  File "c:\users\alec\appdata\local\programs\python\python38\lib\site-packages\flask\app.py", line 1935, in dispatch_request
    return self.view_functions[rule.endpoint](**req.view_args)
  File "c:\users\alec\appdata\local\programs\python\python38\lib\site-packages\flask_login\utils.py", line 272, in decorated_view
    return func(*args, **kwargs)
  File "C:\Users\Alec\Documents\Development\FlaskStuff\microblog\app\main\routes.py", line 142, in search
    posts, total = Post.search(g.search_form.q.data, page,
  File "C:\Users\Alec\Documents\Development\FlaskStuff\microblog\app\models.py", line 15, in search
    ids, total = query_index(cls.__tablename__, expression, page, per_page)
  File "C:\Users\Alec\Documents\Development\FlaskStuff\microblog\app\search.py", line 19, in query_index
    search = current_app.elasticsearch.search(
  File "c:\users\alec\appdata\local\programs\python\python38\lib\site-packages\elasticsearch\client\utils.py", line 84, in _wrapped
    return func(*args, params=params, **kwargs)
  File "c:\users\alec\appdata\local\programs\python\python38\lib\site-packages\elasticsearch\client\__init__.py", line 1547, in search
    return self.transport.perform_request(
  File "c:\users\alec\appdata\local\programs\python\python38\lib\site-packages\elasticsearch\transport.py", line 351, in perform_request
    status, headers_response, data = connection.perform_request(
  File "c:\users\alec\appdata\local\programs\python\python38\lib\site-packages\elasticsearch\connection\http_urllib3.py", line 261, in perform_request
    self._raise_error(response.status, raw_data)
  File "c:\users\alec\appdata\local\programs\python\python38\lib\site-packages\elasticsearch\connection\base.py", line 181, in _raise_error
    raise HTTP_EXCEPTIONS.get(status_code, TransportError)(
elasticsearch.exceptions.NotFoundError: NotFoundError(404, 'index_not_found_exception', 'no such index [post]', post, index_or_alias)
