2020-03-15 11:59:42,106 INFO: Microblog startup [in /Users/alecreid/Desktop/RestApp/FlaskStuff/microblog/app/__init__.py:43]
2020-03-15 11:59:55,980 INFO: Microblog startup [in /Users/alecreid/Desktop/RestApp/FlaskStuff/microblog/app/__init__.py:43]
2020-03-15 13:14:06,286 INFO: Microblog startup [in /Users/alecreid/Desktop/RestApp/FlaskStuff/microblog/app/__init__.py:43]
2020-03-15 13:14:43,694 INFO: Microblog startup [in /Users/alecreid/Desktop/RestApp/FlaskStuff/microblog/app/__init__.py:43]
2020-03-15 13:22:11,361 INFO: Microblog startup [in /Users/alecreid/Desktop/RestApp/FlaskStuff/microblog/app/__init__.py:43]
2020-03-15 13:23:05,443 INFO: Microblog startup [in /Users/alecreid/Desktop/RestApp/FlaskStuff/microblog/app/__init__.py:43]
2020-03-15 16:35:43,201 INFO: Microblog startup [in /Users/alecreid/Desktop/RestApp/FlaskStuff/microblog/app/__init__.py:43]
2020-03-15 16:35:51,473 ERROR: Exception on / [GET] [in /Library/Frameworks/Python.framework/Versions/3.8/lib/python3.8/site-packages/flask/app.py:1890]
Traceback (most recent call last):
  File "/Library/Frameworks/Python.framework/Versions/3.8/lib/python3.8/site-packages/flask/app.py", line 2446, in wsgi_app
    response = self.full_dispatch_request()
  File "/Library/Frameworks/Python.framework/Versions/3.8/lib/python3.8/site-packages/flask/app.py", line 1951, in full_dispatch_request
    rv = self.handle_user_exception(e)
  File "/Library/Frameworks/Python.framework/Versions/3.8/lib/python3.8/site-packages/flask/app.py", line 1820, in handle_user_exception
    reraise(exc_type, exc_value, tb)
  File "/Library/Frameworks/Python.framework/Versions/3.8/lib/python3.8/site-packages/flask/_compat.py", line 39, in reraise
    raise value
  File "/Library/Frameworks/Python.framework/Versions/3.8/lib/python3.8/site-packages/flask/app.py", line 1949, in full_dispatch_request
    rv = self.dispatch_request()
  File "/Library/Frameworks/Python.framework/Versions/3.8/lib/python3.8/site-packages/flask/app.py", line 1935, in dispatch_request
    return self.view_functions[rule.endpoint](**req.view_args)
  File "/Library/Frameworks/Python.framework/Versions/3.8/lib/python3.8/site-packages/flask_login/utils.py", line 272, in decorated_view
    return func(*args, **kwargs)
  File "/Users/alecreid/Desktop/RestApp/FlaskStuff/microblog/app/routes.py", line 28, in index
    posts = current_user.followed.posts().all()
AttributeError: 'AppenderBaseQuery' object has no attribute 'posts'
2020-03-15 16:36:06,881 ERROR: Exception on /index [GET] [in /Library/Frameworks/Python.framework/Versions/3.8/lib/python3.8/site-packages/flask/app.py:1890]
Traceback (most recent call last):
  File "/Library/Frameworks/Python.framework/Versions/3.8/lib/python3.8/site-packages/flask/app.py", line 2446, in wsgi_app
    response = self.full_dispatch_request()
  File "/Library/Frameworks/Python.framework/Versions/3.8/lib/python3.8/site-packages/flask/app.py", line 1951, in full_dispatch_request
    rv = self.handle_user_exception(e)
  File "/Library/Frameworks/Python.framework/Versions/3.8/lib/python3.8/site-packages/flask/app.py", line 1820, in handle_user_exception
    reraise(exc_type, exc_value, tb)
  File "/Library/Frameworks/Python.framework/Versions/3.8/lib/python3.8/site-packages/flask/_compat.py", line 39, in reraise
    raise value
  File "/Library/Frameworks/Python.framework/Versions/3.8/lib/python3.8/site-packages/flask/app.py", line 1949, in full_dispatch_request
    rv = self.dispatch_request()
  File "/Library/Frameworks/Python.framework/Versions/3.8/lib/python3.8/site-packages/flask/app.py", line 1935, in dispatch_request
    return self.view_functions[rule.endpoint](**req.view_args)
  File "/Library/Frameworks/Python.framework/Versions/3.8/lib/python3.8/site-packages/flask_login/utils.py", line 272, in decorated_view
    return func(*args, **kwargs)
  File "/Users/alecreid/Desktop/RestApp/FlaskStuff/microblog/app/routes.py", line 28, in index
    posts = current_user.followed.posts().all()
AttributeError: 'AppenderBaseQuery' object has no attribute 'posts'
2020-03-15 16:39:55,252 INFO: Microblog startup [in /Users/alecreid/Desktop/RestApp/FlaskStuff/microblog/app/__init__.py:43]
2020-03-15 16:42:31,251 INFO: Microblog startup [in /Users/alecreid/Desktop/RestApp/FlaskStuff/microblog/app/__init__.py:43]
2020-03-15 16:42:35,475 ERROR: Exception on /index [GET] [in /Library/Frameworks/Python.framework/Versions/3.8/lib/python3.8/site-packages/flask/app.py:1890]
Traceback (most recent call last):
  File "/Library/Frameworks/Python.framework/Versions/3.8/lib/python3.8/site-packages/flask/app.py", line 2446, in wsgi_app
    response = self.full_dispatch_request()
  File "/Library/Frameworks/Python.framework/Versions/3.8/lib/python3.8/site-packages/flask/app.py", line 1951, in full_dispatch_request
    rv = self.handle_user_exception(e)
  File "/Library/Frameworks/Python.framework/Versions/3.8/lib/python3.8/site-packages/flask/app.py", line 1820, in handle_user_exception
    reraise(exc_type, exc_value, tb)
  File "/Library/Frameworks/Python.framework/Versions/3.8/lib/python3.8/site-packages/flask/_compat.py", line 39, in reraise
    raise value
  File "/Library/Frameworks/Python.framework/Versions/3.8/lib/python3.8/site-packages/flask/app.py", line 1949, in full_dispatch_request
    rv = self.dispatch_request()
  File "/Library/Frameworks/Python.framework/Versions/3.8/lib/python3.8/site-packages/flask/app.py", line 1935, in dispatch_request
    return self.view_functions[rule.endpoint](**req.view_args)
  File "/Library/Frameworks/Python.framework/Versions/3.8/lib/python3.8/site-packages/flask_login/utils.py", line 272, in decorated_view
    return func(*args, **kwargs)
  File "/Users/alecreid/Desktop/RestApp/FlaskStuff/microblog/app/routes.py", line 29, in index
    return render_template("index.html", title='Home Page', form=form,
  File "/Library/Frameworks/Python.framework/Versions/3.8/lib/python3.8/site-packages/flask/templating.py", line 138, in render_template
    ctx.app.jinja_env.get_or_select_template(template_name_or_list),
  File "/Library/Frameworks/Python.framework/Versions/3.8/lib/python3.8/site-packages/jinja2/environment.py", line 930, in get_or_select_template
    return self.get_template(template_name_or_list, parent, globals)
  File "/Library/Frameworks/Python.framework/Versions/3.8/lib/python3.8/site-packages/jinja2/environment.py", line 883, in get_template
    return self._load_template(name, self.make_globals(globals))
  File "/Library/Frameworks/Python.framework/Versions/3.8/lib/python3.8/site-packages/jinja2/environment.py", line 857, in _load_template
    template = self.loader.load(self, name, globals)
  File "/Library/Frameworks/Python.framework/Versions/3.8/lib/python3.8/site-packages/jinja2/loaders.py", line 129, in load
    code = environment.compile(source, name, filename)
  File "/Library/Frameworks/Python.framework/Versions/3.8/lib/python3.8/site-packages/jinja2/environment.py", line 638, in compile
    self.handle_exception(source=source_hint)
  File "/Library/Frameworks/Python.framework/Versions/3.8/lib/python3.8/site-packages/jinja2/environment.py", line 832, in handle_exception
    reraise(*rewrite_traceback_stack(source=source))
  File "/Library/Frameworks/Python.framework/Versions/3.8/lib/python3.8/site-packages/jinja2/_compat.py", line 28, in reraise
    raise value.with_traceback(tb)
  File "/Users/alecreid/Desktop/RestApp/FlaskStuff/microblog/app/templates/index.html", line 24, in template
    {% endfor %}
jinja2.exceptions.TemplateSyntaxError: Encountered unknown tag 'endfor'. Jinja was looking for the following tags: 'endblock'. The innermost block that needs to be closed is 'block'.
