2020-03-18 13:20:14,930 ERROR: Exception on / [GET] [in c:\users\alec\appdata\local\programs\python\python38\lib\site-packages\flask\app.py:1890]
Traceback (most recent call last):
  File "c:\users\alec\appdata\local\programs\python\python38\lib\site-packages\flask\app.py", line 2446, in wsgi_app
    response = self.full_dispatch_request()
  File "c:\users\alec\appdata\local\programs\python\python38\lib\site-packages\flask\app.py", line 1951, in full_dispatch_request
    rv = self.handle_user_exception(e)
  File "c:\users\alec\appdata\local\programs\python\python38\lib\site-packages\flask\app.py", line 1820, in handle_user_exception
    reraise(exc_type, exc_value, tb)
  File "c:\users\alec\appdata\local\programs\python\python38\lib\site-packages\flask\_compat.py", line 39, in reraise
    raise value
  File "c:\users\alec\appdata\local\programs\python\python38\lib\site-packages\flask\app.py", line 1949, in full_dispatch_request
    rv = self.dispatch_request()
  File "c:\users\alec\appdata\local\programs\python\python38\lib\site-packages\flask\app.py", line 1935, in dispatch_request
    return self.view_functions[rule.endpoint](**req.view_args)
  File "c:\users\alec\appdata\local\programs\python\python38\lib\site-packages\flask_login\utils.py", line 272, in decorated_view
    return func(*args, **kwargs)
  File "C:\Users\Alec\Documents\Development\FlaskStuff\microblog\app\main\routes.py", line 44, in index
    return render_template('index.html', title=_('Home'), form=form,
  File "c:\users\alec\appdata\local\programs\python\python38\lib\site-packages\flask\templating.py", line 137, in render_template
    return _render(
  File "c:\users\alec\appdata\local\programs\python\python38\lib\site-packages\flask\templating.py", line 120, in _render
    rv = template.render(context)
  File "c:\users\alec\appdata\local\programs\python\python38\lib\site-packages\jinja2\environment.py", line 1090, in render
    self.environment.handle_exception()
  File "c:\users\alec\appdata\local\programs\python\python38\lib\site-packages\jinja2\environment.py", line 832, in handle_exception
    reraise(*rewrite_traceback_stack(source=source))
  File "c:\users\alec\appdata\local\programs\python\python38\lib\site-packages\jinja2\_compat.py", line 28, in reraise
    raise value.with_traceback(tb)
  File "C:\Users\Alec\Documents\Development\FlaskStuff\microblog\app\templates\index.html", line 2, in top-level template code
    {% import 'bootstrap/wtf.html' as wtf %}
  File "C:\Users\Alec\Documents\Development\FlaskStuff\microblog\app\templates\base.html", line 1, in top-level template code
    {% extends 'bootstrap/base.html' %}
  File "c:\users\alec\appdata\local\programs\python\python38\lib\site-packages\flask_bootstrap\templates\bootstrap\base.html", line 1, in top-level template code
    {% block doc -%}
  File "c:\users\alec\appdata\local\programs\python\python38\lib\site-packages\flask_bootstrap\templates\bootstrap\base.html", line 3, in block "doc"
    <html{% block html_attribs %}{% endblock html_attribs %}>
  File "c:\users\alec\appdata\local\programs\python\python38\lib\site-packages\flask_bootstrap\templates\bootstrap\base.html", line 11, in block "html"
    {%- endblock metas %}
  File "c:\users\alec\appdata\local\programs\python\python38\lib\site-packages\flask_bootstrap\templates\bootstrap\base.html", line 12, in block "body"
  File "C:\Users\Alec\Documents\Development\FlaskStuff\microblog\app\templates\base.html", line 17, in block "navbar"
    <a class="navbar-brand" href="{{ url_for('index') }}">Microblog</a>
  File "c:\users\alec\appdata\local\programs\python\python38\lib\site-packages\flask\helpers.py", line 370, in url_for
    return appctx.app.handle_url_build_error(error, endpoint, values)
  File "c:\users\alec\appdata\local\programs\python\python38\lib\site-packages\flask\app.py", line 2215, in handle_url_build_error
    reraise(exc_type, exc_value, tb)
  File "c:\users\alec\appdata\local\programs\python\python38\lib\site-packages\flask\_compat.py", line 39, in reraise
    raise value
  File "c:\users\alec\appdata\local\programs\python\python38\lib\site-packages\flask\helpers.py", line 357, in url_for
    rv = url_adapter.build(
  File "c:\users\alec\appdata\local\programs\python\python38\lib\site-packages\werkzeug\routing.py", line 2179, in build
    raise BuildError(endpoint, values, method, self)
werkzeug.routing.BuildError: Could not build url for endpoint 'index'. Did you mean 'main.index' instead?
2020-03-18 13:23:48,060 INFO: Microblog startup [in C:\Users\Alec\Documents\Development\FlaskStuff\microblog\app\__init__.py:74]
2020-03-18 13:24:47,541 INFO: Microblog startup [in C:\Users\Alec\Documents\Development\FlaskStuff\microblog\app\__init__.py:74]
2020-03-18 13:25:47,728 INFO: Microblog startup [in C:\Users\Alec\Documents\Development\FlaskStuff\microblog\app\__init__.py:74]
2020-03-18 13:27:38,869 INFO: Microblog startup [in C:\Users\Alec\Documents\Development\FlaskStuff\microblog\app\__init__.py:74]
2020-03-18 14:55:58,318 INFO: Microblog startup [in C:\Users\Alec\Documents\Development\FlaskStuff\microblog\app\__init__.py:77]
2020-03-18 15:00:39,978 INFO: Microblog startup [in C:\Users\Alec\Documents\Development\FlaskStuff\microblog\app\__init__.py:77]
2020-03-18 15:00:44,620 INFO: Microblog startup [in C:\Users\Alec\Documents\Development\FlaskStuff\microblog\app\__init__.py:77]
2020-03-18 15:02:20,073 INFO: Microblog startup [in C:\Users\Alec\Documents\Development\FlaskStuff\microblog\app\__init__.py:77]
2020-03-18 15:02:32,042 ERROR: Exception on /search [GET] [in c:\users\alec\appdata\local\programs\python\python38\lib\site-packages\flask\app.py:1890]
Traceback (most recent call last):
  File "c:\users\alec\appdata\local\programs\python\python38\lib\site-packages\flask\app.py", line 2446, in wsgi_app
    response = self.full_dispatch_request()
  File "c:\users\alec\appdata\local\programs\python\python38\lib\site-packages\flask\app.py", line 1951, in full_dispatch_request
    rv = self.handle_user_exception(e)
  File "c:\users\alec\appdata\local\programs\python\python38\lib\site-packages\flask\app.py", line 1820, in handle_user_exception
    reraise(exc_type, exc_value, tb)
  File "c:\users\alec\appdata\local\programs\python\python38\lib\site-packages\flask\_compat.py", line 39, in reraise
    raise value
  File "c:\users\alec\appdata\local\programs\python\python38\lib\site-packages\flask\app.py", line 1949, in full_dispatch_request
    rv = self.dispatch_request()
  File "c:\users\alec\appdata\local\programs\python\python38\lib\site-packages\flask\app.py", line 1935, in dispatch_request
    return self.view_functions[rule.endpoint](**req.view_args)
  File "c:\users\alec\appdata\local\programs\python\python38\lib\site-packages\flask_login\utils.py", line 272, in decorated_view
    return func(*args, **kwargs)
  File "C:\Users\Alec\Documents\Development\FlaskStuff\microblog\app\main\routes.py", line 142, in search
    posts, total = Post.search(g.search_form.q.data, page,
  File "C:\Users\Alec\Documents\Development\FlaskStuff\microblog\app\models.py", line 15, in search
    ids, total = query_index(cls.__tablename__, expression, page, per_page)
  File "C:\Users\Alec\Documents\Development\FlaskStuff\microblog\app\search.py", line 19, in query_index
    search = current_app.elasticsearch.search(
  File "c:\users\alec\appdata\local\programs\python\python38\lib\site-packages\elasticsearch\client\utils.py", line 84, in _wrapped
    return func(*args, params=params, **kwargs)
  File "c:\users\alec\appdata\local\programs\python\python38\lib\site-packages\elasticsearch\client\__init__.py", line 1547, in search
    return self.transport.perform_request(
  File "c:\users\alec\appdata\local\programs\python\python38\lib\site-packages\elasticsearch\transport.py", line 351, in perform_request
    status, headers_response, data = connection.perform_request(
  File "c:\users\alec\appdata\local\programs\python\python38\lib\site-packages\elasticsearch\connection\http_urllib3.py", line 261, in perform_request
    self._raise_error(response.status, raw_data)
  File "c:\users\alec\appdata\local\programs\python\python38\lib\site-packages\elasticsearch\connection\base.py", line 181, in _raise_error
    raise HTTP_EXCEPTIONS.get(status_code, TransportError)(
elasticsearch.exceptions.NotFoundError: NotFoundError(404, 'index_not_found_exception', 'no such index [post]', post, index_or_alias)
2020-03-18 15:08:38,110 INFO: Microblog startup [in C:\Users\Alec\Documents\Development\FlaskStuff\microblog\app\__init__.py:77]
