2020-03-15 11:30:45,326 ERROR: Exception on /edit_profile [POST] [in /Library/Frameworks/Python.framework/Versions/3.8/lib/python3.8/site-packages/flask/app.py:1890]
Traceback (most recent call last):
  File "/Library/Frameworks/Python.framework/Versions/3.8/lib/python3.8/site-packages/sqlalchemy/engine/base.py", line 1247, in _execute_context
    self.dialect.do_execute(
  File "/Library/Frameworks/Python.framework/Versions/3.8/lib/python3.8/site-packages/sqlalchemy/engine/default.py", line 588, in do_execute
    cursor.execute(statement, parameters)
sqlite3.IntegrityError: UNIQUE constraint failed: user.username

The above exception was the direct cause of the following exception:

Traceback (most recent call last):
  File "/Library/Frameworks/Python.framework/Versions/3.8/lib/python3.8/site-packages/flask/app.py", line 2446, in wsgi_app
    response = self.full_dispatch_request()
  File "/Library/Frameworks/Python.framework/Versions/3.8/lib/python3.8/site-packages/flask/app.py", line 1951, in full_dispatch_request
    rv = self.handle_user_exception(e)
  File "/Library/Frameworks/Python.framework/Versions/3.8/lib/python3.8/site-packages/flask/app.py", line 1820, in handle_user_exception
    reraise(exc_type, exc_value, tb)
  File "/Library/Frameworks/Python.framework/Versions/3.8/lib/python3.8/site-packages/flask/_compat.py", line 39, in reraise
    raise value
  File "/Library/Frameworks/Python.framework/Versions/3.8/lib/python3.8/site-packages/flask/app.py", line 1949, in full_dispatch_request
    rv = self.dispatch_request()
  File "/Library/Frameworks/Python.framework/Versions/3.8/lib/python3.8/site-packages/flask/app.py", line 1935, in dispatch_request
    return self.view_functions[rule.endpoint](**req.view_args)
  File "/Library/Frameworks/Python.framework/Versions/3.8/lib/python3.8/site-packages/flask_login/utils.py", line 272, in decorated_view
    return func(*args, **kwargs)
  File "/Users/alecreid/Desktop/RestApp/FlaskStuff/microblog/app/routes.py", line 87, in edit_profile
    db.session.commit()
  File "/Library/Frameworks/Python.framework/Versions/3.8/lib/python3.8/site-packages/sqlalchemy/orm/scoping.py", line 162, in do
    return getattr(self.registry(), name)(*args, **kwargs)
  File "/Library/Frameworks/Python.framework/Versions/3.8/lib/python3.8/site-packages/sqlalchemy/orm/session.py", line 1036, in commit
    self.transaction.commit()
  File "/Library/Frameworks/Python.framework/Versions/3.8/lib/python3.8/site-packages/sqlalchemy/orm/session.py", line 503, in commit
    self._prepare_impl()
  File "/Library/Frameworks/Python.framework/Versions/3.8/lib/python3.8/site-packages/sqlalchemy/orm/session.py", line 482, in _prepare_impl
    self.session.flush()
  File "/Library/Frameworks/Python.framework/Versions/3.8/lib/python3.8/site-packages/sqlalchemy/orm/session.py", line 2496, in flush
    self._flush(objects)
  File "/Library/Frameworks/Python.framework/Versions/3.8/lib/python3.8/site-packages/sqlalchemy/orm/session.py", line 2637, in _flush
    transaction.rollback(_capture_exception=True)
  File "/Library/Frameworks/Python.framework/Versions/3.8/lib/python3.8/site-packages/sqlalchemy/util/langhelpers.py", line 68, in __exit__
    compat.raise_(
  File "/Library/Frameworks/Python.framework/Versions/3.8/lib/python3.8/site-packages/sqlalchemy/util/compat.py", line 178, in raise_
    raise exception
  File "/Library/Frameworks/Python.framework/Versions/3.8/lib/python3.8/site-packages/sqlalchemy/orm/session.py", line 2597, in _flush
    flush_context.execute()
  File "/Library/Frameworks/Python.framework/Versions/3.8/lib/python3.8/site-packages/sqlalchemy/orm/unitofwork.py", line 422, in execute
    rec.execute(self)
  File "/Library/Frameworks/Python.framework/Versions/3.8/lib/python3.8/site-packages/sqlalchemy/orm/unitofwork.py", line 586, in execute
    persistence.save_obj(
  File "/Library/Frameworks/Python.framework/Versions/3.8/lib/python3.8/site-packages/sqlalchemy/orm/persistence.py", line 230, in save_obj
    _emit_update_statements(
  File "/Library/Frameworks/Python.framework/Versions/3.8/lib/python3.8/site-packages/sqlalchemy/orm/persistence.py", line 994, in _emit_update_statements
    c = cached_connections[connection].execute(
  File "/Library/Frameworks/Python.framework/Versions/3.8/lib/python3.8/site-packages/sqlalchemy/engine/base.py", line 984, in execute
    return meth(self, multiparams, params)
  File "/Library/Frameworks/Python.framework/Versions/3.8/lib/python3.8/site-packages/sqlalchemy/sql/elements.py", line 293, in _execute_on_connection
    return connection._execute_clauseelement(self, multiparams, params)
  File "/Library/Frameworks/Python.framework/Versions/3.8/lib/python3.8/site-packages/sqlalchemy/engine/base.py", line 1097, in _execute_clauseelement
    ret = self._execute_context(
  File "/Library/Frameworks/Python.framework/Versions/3.8/lib/python3.8/site-packages/sqlalchemy/engine/base.py", line 1287, in _execute_context
    self._handle_dbapi_exception(
  File "/Library/Frameworks/Python.framework/Versions/3.8/lib/python3.8/site-packages/sqlalchemy/engine/base.py", line 1481, in _handle_dbapi_exception
    util.raise_(
  File "/Library/Frameworks/Python.framework/Versions/3.8/lib/python3.8/site-packages/sqlalchemy/util/compat.py", line 178, in raise_
    raise exception
  File "/Library/Frameworks/Python.framework/Versions/3.8/lib/python3.8/site-packages/sqlalchemy/engine/base.py", line 1247, in _execute_context
    self.dialect.do_execute(
  File "/Library/Frameworks/Python.framework/Versions/3.8/lib/python3.8/site-packages/sqlalchemy/engine/default.py", line 588, in do_execute
    cursor.execute(statement, parameters)
sqlalchemy.exc.IntegrityError: (sqlite3.IntegrityError) UNIQUE constraint failed: user.username
[SQL: UPDATE user SET username=?, about_me=? WHERE user.id = ?]
[parameters: ('alec123', 'derp derp derp\r\n', 2)]
(Background on this error at: http://sqlalche.me/e/gkpj)
2020-03-15 11:31:51,581 INFO: Microblog startup [in /Users/alecreid/Desktop/RestApp/FlaskStuff/microblog/app/__init__.py:43]
2020-03-15 11:31:55,272 ERROR: Exception on /edit_profile [GET] [in /Library/Frameworks/Python.framework/Versions/3.8/lib/python3.8/site-packages/flask/app.py:1890]
Traceback (most recent call last):
  File "/Library/Frameworks/Python.framework/Versions/3.8/lib/python3.8/site-packages/flask/app.py", line 2446, in wsgi_app
    response = self.full_dispatch_request()
  File "/Library/Frameworks/Python.framework/Versions/3.8/lib/python3.8/site-packages/flask/app.py", line 1951, in full_dispatch_request
    rv = self.handle_user_exception(e)
  File "/Library/Frameworks/Python.framework/Versions/3.8/lib/python3.8/site-packages/flask/app.py", line 1820, in handle_user_exception
    reraise(exc_type, exc_value, tb)
  File "/Library/Frameworks/Python.framework/Versions/3.8/lib/python3.8/site-packages/flask/_compat.py", line 39, in reraise
    raise value
  File "/Library/Frameworks/Python.framework/Versions/3.8/lib/python3.8/site-packages/flask/app.py", line 1949, in full_dispatch_request
    rv = self.dispatch_request()
  File "/Library/Frameworks/Python.framework/Versions/3.8/lib/python3.8/site-packages/flask/app.py", line 1935, in dispatch_request
    return self.view_functions[rule.endpoint](**req.view_args)
  File "/Library/Frameworks/Python.framework/Versions/3.8/lib/python3.8/site-packages/flask_login/utils.py", line 272, in decorated_view
    return func(*args, **kwargs)
  File "/Users/alecreid/Desktop/RestApp/FlaskStuff/microblog/app/routes.py", line 83, in edit_profile
    form = EditProfileForm(current_user.username.data)
AttributeError: 'str' object has no attribute 'data'
2020-03-15 11:32:40,353 ERROR: Exception on /edit_profile [GET] [in /Library/Frameworks/Python.framework/Versions/3.8/lib/python3.8/site-packages/flask/app.py:1890]
Traceback (most recent call last):
  File "/Library/Frameworks/Python.framework/Versions/3.8/lib/python3.8/site-packages/flask/app.py", line 2446, in wsgi_app
    response = self.full_dispatch_request()
  File "/Library/Frameworks/Python.framework/Versions/3.8/lib/python3.8/site-packages/flask/app.py", line 1951, in full_dispatch_request
    rv = self.handle_user_exception(e)
  File "/Library/Frameworks/Python.framework/Versions/3.8/lib/python3.8/site-packages/flask/app.py", line 1820, in handle_user_exception
    reraise(exc_type, exc_value, tb)
  File "/Library/Frameworks/Python.framework/Versions/3.8/lib/python3.8/site-packages/flask/_compat.py", line 39, in reraise
    raise value
  File "/Library/Frameworks/Python.framework/Versions/3.8/lib/python3.8/site-packages/flask/app.py", line 1949, in full_dispatch_request
    rv = self.dispatch_request()
  File "/Library/Frameworks/Python.framework/Versions/3.8/lib/python3.8/site-packages/flask/app.py", line 1935, in dispatch_request
    return self.view_functions[rule.endpoint](**req.view_args)
  File "/Library/Frameworks/Python.framework/Versions/3.8/lib/python3.8/site-packages/flask_login/utils.py", line 272, in decorated_view
    return func(*args, **kwargs)
  File "/Users/alecreid/Desktop/RestApp/FlaskStuff/microblog/app/routes.py", line 83, in edit_profile
    form = EditProfileForm(current_user.username)
AttributeError: 'str' object has no attribute 'data'
2020-03-15 11:32:45,664 INFO: Microblog startup [in /Users/alecreid/Desktop/RestApp/FlaskStuff/microblog/app/__init__.py:43]
2020-03-15 11:33:44,266 INFO: Microblog startup [in /Users/alecreid/Desktop/RestApp/FlaskStuff/microblog/app/__init__.py:43]
2020-03-15 11:35:42,125 INFO: Microblog startup [in /Users/alecreid/Desktop/RestApp/FlaskStuff/microblog/app/__init__.py:43]
2020-03-15 11:36:03,750 INFO: Microblog startup [in /Users/alecreid/Desktop/RestApp/FlaskStuff/microblog/app/__init__.py:43]
2020-03-15 11:36:54,758 INFO: Microblog startup [in /Users/alecreid/Desktop/RestApp/FlaskStuff/microblog/app/__init__.py:43]
2020-03-15 11:58:07,732 INFO: Microblog startup [in /Users/alecreid/Desktop/RestApp/FlaskStuff/microblog/app/__init__.py:43]
2020-03-15 11:58:47,939 INFO: Microblog startup [in /Users/alecreid/Desktop/RestApp/FlaskStuff/microblog/app/__init__.py:43]
